<?xml version='1.0'?>
<sdf version='1.7'>
  <model name='model2'>
    <link name='base_link'>
      <inertial>
        <pose>-0 -0 0.306512 0 -0 0</pose>
        <mass>106.315</mass>
        <inertia>
          <ixx>12.9223</ixx>
          <ixy>-4.43734e-31</ixy>
          <ixz>2.53689e-15</ixz>
          <iyy>12.9223</iyy>
          <iyz>9.54385e-15</iyz>
          <izz>2.07993</izz>
        </inertia>
      </inertial>
      <collision name='base_link_collision'>
        <pose>0 0 0 0 -0 0</pose>
        <geometry>
          <mesh>
            <scale>1 1 1</scale>
            <uri>model://model2/meshes/base_link.STL</uri>
          </mesh>
        </geometry>
      </collision>
      <visual name='base_link_visual'>
        <pose>0 0 0 0 -0 0</pose>
        <geometry>
          <mesh>
            <scale>1 1 1</scale>
            <uri>model://model2/meshes/base_link.STL</uri>
          </mesh>
        </geometry>
      </visual>
    </link>
    <joint name='R1' type='revolute'>
      <pose relative_to='base_link'>0 0 1.02 1.5708 -0 0</pose>
      <parent>base_link</parent>
      <child>link2</child>
      <axis>
        <xyz>-1 0 0</xyz>
        <limit>
          <lower>-1e+16</lower>
          <upper>1e+16</upper>
        </limit>
        <dynamics>
          <spring_reference>0</spring_reference>
          <spring_stiffness>0</spring_stiffness>
        </dynamics>
      </axis>
    </joint>
    <link name='link2'>
      <pose relative_to='R1'>0 0 0 0 -0 0</pose>
      <inertial>
        <pose>0 0 0.25 0 -0 0</pose>
        <mass>30.5497</mass>
        <inertia>
          <ixx>0.655737</ixx>
          <ixy>1.40836e-32</ixy>
          <ixz>3.52682e-17</ixz>
          <iyy>0.655737</iyy>
          <iyz>-2.17446e-16</iyz>
          <izz>0.038569</izz>
        </inertia>
      </inertial>
      <collision name='link2_collision'>
        <pose>0 0 0 0 -0 0</pose>
        <geometry>
          <mesh>
            <scale>1 1 1</scale>
            <uri>model://model2/meshes/link2.STL</uri>
          </mesh>
        </geometry>
      </collision>
      <visual name='link2_visual'>
        <pose>0 0 0 0 -0 0</pose>
        <geometry>
          <mesh>
            <scale>1 1 1</scale>
            <uri>model://model2/meshes/link2.STL</uri>
          </mesh>
        </geometry>
      </visual>
    </link>
    <joint name='R2' type='revolute'>
      <pose relative_to='link2'>0 0 0.5 0 -0 0</pose>
      <parent>link2</parent>
      <child>link3</child>
      <axis>
        <xyz>1 0 0</xyz>
        <limit>
          <lower>-1e+16</lower>
          <upper>1e+16</upper>
        </limit>
        <dynamics>
          <spring_reference>0</spring_reference>
          <spring_stiffness>0</spring_stiffness>
        </dynamics>
      </axis>
    </joint>
    <link name='link3'>
      <pose relative_to='R2'>0 0 0 0 -0 0</pose>
      <inertial>
        <pose>0 0 0.2 0 -0 0</pose>
        <mass>8.39748</mass>
        <inertia>
          <ixx>0.117267</ixx>
          <ixy>-1.44309e-34</ixy>
          <ixz>-6.66442e-18</ixz>
          <iyy>0.117267</iyy>
          <iyz>-7.81276e-18</iyz>
          <izz>0.0106018</izz>
        </inertia>
      </inertial>
      <collision name='link3_collision'>
        <pose>0 0 0 0 -0 0</pose>
        <geometry>
          <mesh>
            <scale>1 1 1</scale>
            <uri>model://model2/meshes/link3.STL</uri>
          </mesh>
        </geometry>
      </collision>
      <visual name='link3_visual'>
        <pose>0 0 0 0 -0 0</pose>
        <geometry>
          <mesh>
            <scale>1 1 1</scale>
            <uri>model://model2/meshes/link3.STL</uri>
          </mesh>
        </geometry>
      </visual>
    </link>


    <!--fixing base_link to world-->
    <link name="world_fix"></link>
    <joint name ="weld" type="fixed">
      <parent>world</parent>
      <child>base_link</child>
    </joint>
    <!--fixing base_link to world-->


    <plugin name="gazebo_ros_force" filename="libgazebo_ros_force.so">
      <ros>
        <namespace>/demo/link2</namespace>
        <remapping>gazebo_ros_force:=force_demo2</remapping>
      </ros>
      <link_name>link2</link_name>
      <force_frame>link</force_frame>
    </plugin>

    <plugin name="gazebo_ros_force" filename="libgazebo_ros_force.so">
      <ros>
        <namespace>/demo/link3</namespace>
        <remapping>gazebo_ros_force:=force_demo3</remapping>
      </ros>
      <link_name>link3</link_name>
      <force_frame>link</force_frame>
    </plugin>





    <plugin name='joint_publisher' filename='libgazebo_ros_joint_state_publisher.so'>
      <ros>
        <namespace>/myrobot/R1</namespace>
      </ros>
      <update_rate>1000.0</update_rate>
      <joint_name>R1</joint_name>
    </plugin>

    <plugin name='joint_publisher' filename='libgazebo_ros_joint_state_publisher.so'>
      <ros>
        <namespace>/myrobot/R2</namespace>
      </ros>
      <update_rate>1000.0</update_rate>
      <joint_name>R2</joint_name>
    </plugin>  


  </model>
</sdf>
