<sdf version='1.7'>
  <world name='world1'>
    <light name='sun' type='directional'>
      <cast_shadows>1</cast_shadows>
      <pose>0 0 10 0 -0 0</pose>
      <diffuse>0.8 0.8 0.8 1</diffuse>
      <specular>0.2 0.2 0.2 1</specular>
      <attenuation>
        <range>1000</range>
        <constant>0.9</constant>
        <linear>0.01</linear>
        <quadratic>0.001</quadratic>
      </attenuation>
      <direction>-0.5 0.1 -0.9</direction>
      <spot>
        <inner_angle>0</inner_angle>
        <outer_angle>0</outer_angle>
        <falloff>0</falloff>
      </spot>
    </light>
    <model name='ground_plane'>
      <static>1</static>
      <link name='link'>
        <collision name='collision'>
          <geometry>
            <plane>
              <normal>0 0 1</normal>
              <size>100 100</size>
            </plane>
          </geometry>
          <surface>
            <contact>
              <collide_bitmask>65535</collide_bitmask>
              <ode/>
            </contact>
            <friction>
              <ode>
                <mu>100</mu>
                <mu2>50</mu2>
              </ode>
              <torsional>
                <ode/>
              </torsional>
            </friction>
            <bounce/>
          </surface>
          <max_contacts>10</max_contacts>
        </collision>
        <visual name='visual'>
          <cast_shadows>0</cast_shadows>
          <geometry>
            <plane>
              <normal>0 0 1</normal>
              <size>100 100</size>
            </plane>
          </geometry>
          <material>
            <script>
              <uri>file://media/materials/scripts/gazebo.material</uri>
              <name>Gazebo/Grey</name>
            </script>
          </material>
        </visual>
        <self_collide>0</self_collide>
        <enable_wind>0</enable_wind>
        <kinematic>0</kinematic>
      </link>
    </model>
    <gravity>0 0 -9.8</gravity>
    <magnetic_field>6e-06 2.3e-05 -4.2e-05</magnetic_field>
    <atmosphere type='adiabatic'/>
    <physics type='ode'>
      <max_step_size>0.001</max_step_size>
      <real_time_factor>1</real_time_factor>
      <real_time_update_rate>1000</real_time_update_rate>
    </physics>
    <scene>
      <ambient>0.4 0.4 0.4 1</ambient>
      <background>0.7 0.7 0.7 1</background>
      <shadows>1</shadows>
    </scene>
    <wind/>
    <spherical_coordinates>
      <surface_model>EARTH_WGS84</surface_model>
      <latitude_deg>0</latitude_deg>
      <longitude_deg>0</longitude_deg>
      <elevation>0</elevation>
      <heading_deg>0</heading_deg>
    </spherical_coordinates>
    <state world_name='default'>
      <sim_time>6 64000000</sim_time>
      <real_time>6 86571308</real_time>
      <wall_time>1643630299 987357236</wall_time>
      <iterations>6064</iterations>
      <model name='ground_plane'>
        <pose>0 0 0 0 -0 0</pose>
        <scale>1 1 1</scale>
        <link name='link'>
          <pose>0 0 0 0 -0 0</pose>
          <velocity>0 0 0 0 -0 0</velocity>
          <acceleration>0 0 0 0 -0 0</acceleration>
          <wrench>0 0 0 0 -0 0</wrench>
        </link>
      </model>
      <light name='sun'>
        <pose>0 0 10 0 -0 0</pose>
      </light>
    </state>
    <gui fullscreen='0'>
      <camera name='user_camera'>
        <pose>5 -5 2 0 0.275643 2.35619</pose>
        <view_controller>orbit</view_controller>
        <projection_type>perspective</projection_type>
      </camera>
    </gui>

    <model name='model1'>
    <pose>0 0 0 -1.57 0 0</pose>



    <link name='base_link'>
      <inertial>
        <pose>0 -0.1593 0 0 -0 0</pose>
        <mass>455.92</mass>
        <inertia>
          <ixx>33.905</ixx>
          <ixy>3.8115e-33</ixy>
          <ixz>-2.5391e-34</ixz>
          <iyy>53.054</iyy>
          <iyz>-1.1725e-15</iyz>
          <izz>33.905</izz>
        </inertia>
      </inertial>
      <collision name='base_link_collision'>
        <pose>0 0 0 0 -0 0</pose>
        <geometry>
          <mesh>
            <scale>1 1 1</scale>
            <uri>/home/delta/ieee_ws/src/applyTorque/models/model1/meshes/base_link.STL</uri>
          </mesh>
        </geometry>
      </collision>
      <visual name='base_link_visual'>
        <pose>0 0 0 0 -0 0</pose>
        <geometry>
          <mesh>
            <scale>1 1 1</scale>
            <uri>/home/delta/ieee_ws/src/applyTorque/models/model1/meshes/base_link.STL</uri>
          </mesh>
        </geometry>
      </visual>
    </link>
    <joint name='R1' type='revolute'>
      <pose relative_to='base_link'>0 -1.7 0 1.5708 -0 -3.14159</pose>
      <parent>base_link</parent>
      <child>link</child>
      <axis>
        <xyz>1 0 0</xyz>
        <limit>
          <lower>-1e+16</lower>
          <upper>1e+16</upper>
        </limit>
        <dynamics>
          <spring_reference>0</spring_reference>
          <spring_stiffness>0</spring_stiffness>
        </dynamics>
      </axis>
    </joint>
    <link name='link'>
      <pose relative_to='R1'>0 0 0 0 -0 0</pose>
      <inertial>
        <pose>-0 0 0.5 0 -0 0</pose>
        <mass>21.206</mass>
        <inertia>
          <ixx>1.7804</ixx>
          <ixy>-3.6279e-33</ixy>
          <ixz>-1.0255e-17</ixz>
          <iyy>1.7804</iyy>
          <iyz>1.223e-32</iyz>
          <izz>0.026507</izz>
        </inertia>
      </inertial>
      <collision name='link_collision'>
        <pose>0 0 0 0 -0 0</pose>
        <geometry>
          <mesh>
            <scale>1 1 1</scale>
            <uri>/home/delta/ieee_ws/src/applyTorque/models/model1/meshes/link.STL</uri>
          </mesh>
        </geometry>
      </collision>
      <visual name='link_visual'>
        <pose>0 0 0 0 -0 0</pose>
        <geometry>
          <mesh>
            <scale>1 1 1</scale>
            <uri>/home/delta/ieee_ws/src/applyTorque/models/model1/meshes/link.STL</uri>
          </mesh>
        </geometry>
      </visual>
    </link>

    <plugin name="gazebo_ros_force" filename="libgazebo_ros_force.so">
      <ros>
        <namespace>/demo/link</namespace>
        <remapping>gazebo_ros_force:=force_demo</remapping>
      </ros>
      <link_name>link</link_name>
      <force_frame>link</force_frame>
    </plugin>


    <plugin name='joint_publisher' filename='libgazebo_ros_joint_state_publisher.so'>
      <ros>
        <namespace>/myrobot</namespace>
      </ros>
      <update_rate>1000.0</update_rate>
      <joint_name>R1</joint_name>
    </plugin>
  </model>

  </world>
</sdf>
